//Finally Clause
// its a family member of try and catch clause
// but it always run

try{
    let a = 0
    console.log(program)
    console.log("Program ran successfully")
}catch(err){
    console.log("This is an error")
    console.log(p)
}
finally{
    console.log("I'm a good girl")
}